20.02.06

# 비동기 프로그래밍1 : 프로미스(p.74)

> 비동기 : 우선 함수를 던지고, 상대방의 처리결과를 확인하지 않고 다음 작업을 처리하는 것

* 프로미스 : 비동기 상태를 값으로 다룰 수 있는 객체
  프로미스를 사용하면, 비동기 프로그래밍을 할 때 동기 프로그래밍 방식으로 코드 작성 가능 (비동기프로그래밍에서도 코드를 순차적으로 작성)
  프로미스 이전에는 콜백 패턴을 많이 사용
  ES6에서 프로미스가 javascript 언어에 포함
* 프로미스 상태
  - 대기중(pending) → 결과를 기다리는 상태
  - 이행됨(fulfilled) → 수행이 정상적으로 끝났고 결과값을 갖고 있는 상태
  - 거부됨(rejected) → 수행이 비정상적으로 끝난 상태
  - 이행됨, 거부됨 상태를 처리됨(settled) 상태라고 함
  - 프로미스는 처리됨(settled) 상태가 되면 더 이상 다른 상태로 변경되지 않으며, 대기중 상태에서만 이행됨, 거부됨 상태로 변경될 수 있음

![img](https://lh3.googleusercontent.com/NYhj-mp6l5LoMObwgajxiEMTAANxYElN9GfnxCFZ7guYUMj0Aqv66IPhOHcNDqYwS_oKV3yT4UuWqLFLEZkQb6qpHoNOpsfdElF6VgwsoiHiIbQpgHImu9ekdW867O5s0luRXKRc)  





## 콜백 패턴의 문제

* 프로미스 이전에 비동기 프로그래밍의 한 가지 방식으로 콜백(callback) 패턴을 많이 사용

  콜백 패턴은 콜백이 조금만 중첩돼도 코드가 복잡해지는 단점

* 콜백 패턴은 코드의 위에서부터 아래로 순차적으로 작동X

  request > function  > console.log 순으로 왔다갔다 실행



## 프로미스 생성

* new 키워드를 사용해 Promise 생성

  ```javascript
  const p1 = new Promise((resolve, reject) => {})
  ```

  * const(constance) : 상수 선언 (한 번 선언하면 재정의 불가)

    `{} 블록` 내에서 scope 가짐. 괄호 바깥에서 재 선언 가능

  * 생성된 프로미스는 대기 중 상태

  * resolve와 reject라는 콜백 함수를 매개변수로 가짐

  * 비동기로 작업을 수행해, 성공하면 resolve(이행됨), 실패하면 reject(거부됨) 호출

* Reject로 거부됨 상태인 Promise 생성

  ```javascript
  const p2 = Promise.reject('error message')
  ```

* Resolve로 이행됨 상태인 Promise 생성

  ```javascript
  const p3 = Promise.resolve('success')
  ```

  



```javascript
const p1 = Promise.resolve(123);
    console.log(p1 === 123);    // false
    console.log(p1);            // Promise {<resolved>: 123}
        
    // new Promise(resolve, reject);
    const p2 = new Promise(
        resolve => { setTimeout(() => resolve('1초 경과'), 1000) }, 
        reject => { return "error" }
    );
    console.log(p2 === Promise.resolve(p2));    // true
    console.log(p2);            //  Promise {<pending>}
    p2.then(data => { 
        console.log(p2);        // Promise {<resolved>: "1초 경과"}
        console.log(data);      // '1초 경과'
    }); 

```



### Reject와 Resolve

* Reject

```javascript
Promise.reject("error message")
.then(() => console.log("#1"))
.then(() => console.log("#2"))
.then(() => console.log("#3"), () => console.log("#3-2"))
.then(() => console.log("#4"), () => console.log("#4-2"));
```

`reject : 실패하는 경우.then(성공을 처리, 실패를 처리)`

#1과 #2는 실패하는 경우에 대한 처리가 없어 통과

#3은 실패한 경우에 따라 "#3-2" 출력하고

실패가 해결되었으므로 성공이 처리된 "#4-1" 출력

![image-20200206093818001](C:\Users\HPE\Desktop\TIL\images\image-20200206093818001.png)



* Reject & Return

```javascript
Promise.reject("error message")
.then(() => console.log("#1"))
.then(() => console.log("#2"))
.then(() => console.log("#3-1"), (data) => {
    console.log("#3-2", data);
    return "hello";
    }
    )
.then((data) => console.log("#4-1", data), () => console.log("#4-2"))
```

실패를 통해 "#3-2"가 도출되고, reject data인 "error message"가 나타남

실패가 처리된 이후에 "hello"를 입력했고, #4에서는 #3에서 입력한 data인 "hello"가 입력되어 성공된 경우에 따라 `#4-1 hello`로 함께 출력

![image-20200206094304261](C:\Users\HPE\Desktop\TIL\images\image-20200206094304261.png)



* Resolve

```javascript
Promise.resolve("message")
    .then((data) => { console.log("#1", data); return "message2"; })
    .then((data) => console.log("#2", data))
    .then(
        () => console.log("#3-1"), 
        (data) => {
            console.log("#3-2", data);
            return "hello";
        }
    )
    .then((data) => console.log("#4-1", data), () => console.log("#4-2"));
```

"message"가 처리되면 `#1`에서 data인 `message`와 함께 나타나고, "message2"가 입력된다. 이는 `#2`에서 데이터로 함께 출력

별도로 입력된 데이터가 없으므로 `#3-1`만 입력되고, 이후 `#4-1`에서는 별도로 입력된 데이터가 없음에도 출력하라고 되어 있어 `#4-1 undefined`가 출력

![image-20200206094922938](C:\Users\HPE\Desktop\TIL\images\image-20200206094922938.png)



* Resolve & Reject

```javascript
Promise.resolve(100)
    .then((data) => { console.log("#1", data); data += 100; return data})
    .then((data) => { console.log("#2", data); data -=50; return data})
    .then((data) => {console.log("#3", data); return Promise.reject("error")})
    .then(null, (data) => console.log("#4", data));
```

처음 값인 100을 입력

성공한 경우에 따라 `#1`에서 처음 데이터인 100이 출력되고, 이후 원래 값에 100을 더해 200이 데이터가 된다.

두번째에 성공한 경우에서 `#2`에서 데이터인 200이 함께 출력되고, 50이 감소해 150이 데이터가 된다.

세번째에 `#3`에서 데이터인 150이 출력되고, reject값인 `error`을 입력한다.

마지막에는 null로 따로 번호를 붙이지 않고, 데이터인 `error`만 출력된다.

![image-20200206100023543](C:\Users\HPE\Desktop\TIL\images\image-20200206100023543.png)



* Catch : 예외처리

  ```javascript
  Promise.reject("error1").then(null, 실패1 => {console.log(실패1) });
  Promise.reject("error2").catch(실패2 => console.log(실패2));
  ```

  * Reject 함수에 비해 Catch가 가독성이 좋다(괄호 및 데이터 감소) : 동일한 결과값 도출됨

  ![image-20200206101058280](C:\Users\HPE\Desktop\TIL\images\image-20200206101058280.png)

  * Resolve 함수 내에서 발생하는 예외처리

  ```javascript
  Promise.resolve(). then(
      () => {
          console.log("#1");
          throw new Error("Error Occured"); 
      },
      (data) => {
          console.log("#2", data); // 이러면 uncaught 오류 발생
      }
  )
     .then(
               null, 
               (data) => {
                   console.log("#3", data);
               }
           );
  ```

  ![image-20200206102300758](C:\Users\HPE\Desktop\TIL\images\image-20200206102300758.png)

Resolve함수를 사용하는 것에 비해 Catch를 사용하면 Throw할 때 쉬움

```javascript

Promise.resolve("data")
        .then(
            (data) => { 
                console.log("#1", data);
                throw new Error("Error Occured");   
            }
        )
        .catch(data => console.log("#4", data));
```

![image-20200206102357722](C:\Users\HPE\Desktop\TIL\images\image-20200206102357722.png)

* Reject와 Return

  ```javascript
      Promise.reject(10)
          .then(data => {
              console.log("then1", data);
              return 20;
          })
          .catch(data => {
              console.log("catch", data);
              return 30;
          })
          .then(data => {
              console.log("then2", data);
          });
  ```

  ![image-20200206102454987](C:\Users\HPE\Desktop\TIL\images\image-20200206102454987.png)



### Finally

```javascript
function sendLogToServer(msg) {
    console.log("sendLogToServer", msg)
}

function requestData() {
    let url = "http://localhost:8080/es6.html";
    return fetch(url)
    .then(resolve => {
        console.log("#1", resolve);
        return resolve;
    })
    .catch(error => {
        console.log("2", error);
        return error;
    })
    
    // then과 finally의 차이 확인하기
    .finally(() => {
        console.log("#3");
        sendLogToServer("requestData Finished");
        //return data;
    });
}
requestData().then(resolve => console.log("#4", resolve));
```

`sendLogToServer`이라는 함수는 `sendLogToServer 메세지내용`이 나타나도록 정의됨

`requestData`함수는 url을 fetch하고, `#1하고 resolve`가 나나탐

`error`이 발생한 경우에는 `#2`가 나타나지만 실패하지 않아 통과..?

이해해보쟈......ㅠㅠㅠㅠㅠ

![image-20200206102944682](C:\Users\HPE\Desktop\TIL\images\image-20200206102944682.png)



* 실습

  ```javascript
  <script>
  
  function requestData1() {
      return Promise.resolve("requestData1 called");
  }
  // 성공한 프로미스 반환
  
  function requestData2() {
      return promise.reject("requestData2 called")
  }
  // 실패한 프로미스 반환
  
  requestData1()
  //Data1을 처리하는데 성공하면 then 수행하고 실패하면 catch 시행
  .then(data =>{
      console.log("#1", data);
      return requestData2();
      //data2를 호출해 다음 then에서 수행할 수 있도록 해줌
  })
  .then(data => {
      console.log("#2", data);
  })
  .catch(error => {
      console.log("ERROR", error);
      //reject는 위에서 Data2를 받아와 error을 통해 설명
  })
  </script>
  ```

  ![image-20200206104607837](C:\Users\HPE\Desktop\TIL\images\image-20200206104607837.png)



